[2024-09-05T01:22:36.596+0000] {local_task_job_runner.py:120} INFO - ::group::Pre task execution logs
[2024-09-05T01:22:36.613+0000] {taskinstance.py:2076} INFO - Dependencies all met for dep_context=non-requeueable deps ti=<TaskInstance: otro_dag.bash_task manual__2024-09-05T01:22:35.758121+00:00 [queued]>
[2024-09-05T01:22:36.620+0000] {taskinstance.py:2076} INFO - Dependencies all met for dep_context=requeueable deps ti=<TaskInstance: otro_dag.bash_task manual__2024-09-05T01:22:35.758121+00:00 [queued]>
[2024-09-05T01:22:36.620+0000] {taskinstance.py:2306} INFO - Starting attempt 1 of 1
[2024-09-05T01:22:36.638+0000] {taskinstance.py:2330} INFO - Executing <Task(BashOperator): bash_task> on 2024-09-05 01:22:35.758121+00:00
[2024-09-05T01:22:36.643+0000] {warnings.py:112} WARNING - /home/***/.local/lib/python3.12/site-packages/***/task/task_runner/standard_task_runner.py:61: DeprecationWarning: This process (pid=147) is multi-threaded, use of fork() may lead to deadlocks in the child.
  pid = os.fork()

[2024-09-05T01:22:36.644+0000] {standard_task_runner.py:63} INFO - Started process 148 to run task
[2024-09-05T01:22:36.645+0000] {standard_task_runner.py:90} INFO - Running: ['***', 'tasks', 'run', 'otro_dag', 'bash_task', 'manual__2024-09-05T01:22:35.758121+00:00', '--job-id', '9', '--raw', '--subdir', 'DAGS_FOLDER/dag_to_fail.py', '--cfg-path', '/tmp/tmpf8cqi5lh']
[2024-09-05T01:22:36.646+0000] {standard_task_runner.py:91} INFO - Job 9: Subtask bash_task
[2024-09-05T01:22:36.700+0000] {task_command.py:426} INFO - Running <TaskInstance: otro_dag.bash_task manual__2024-09-05T01:22:35.758121+00:00 [running]> on host f5e4db2ad780
[2024-09-05T01:22:36.819+0000] {taskinstance.py:2648} INFO - Exporting env vars: AIRFLOW_CTX_DAG_EMAIL='anderson.coder.space@gmail.com' AIRFLOW_CTX_DAG_OWNER='***' AIRFLOW_CTX_DAG_ID='otro_dag' AIRFLOW_CTX_TASK_ID='bash_task' AIRFLOW_CTX_EXECUTION_DATE='2024-09-05T01:22:35.758121+00:00' AIRFLOW_CTX_TRY_NUMBER='1' AIRFLOW_CTX_DAG_RUN_ID='manual__2024-09-05T01:22:35.758121+00:00'
[2024-09-05T01:22:36.820+0000] {taskinstance.py:430} INFO - ::endgroup::
[2024-09-05T01:22:36.836+0000] {subprocess.py:63} INFO - Tmp dir root location: /tmp
[2024-09-05T01:22:36.837+0000] {subprocess.py:75} INFO - Running command: ['/usr/bin/bash', '-c', 'echo "Here is the message: Hello,world!" && exit 1']
[2024-09-05T01:22:36.848+0000] {subprocess.py:86} INFO - Output:
[2024-09-05T01:22:36.851+0000] {subprocess.py:93} INFO - Here is the message: Hello,world!
[2024-09-05T01:22:36.852+0000] {subprocess.py:97} INFO - Command exited with return code 1
[2024-09-05T01:22:36.853+0000] {taskinstance.py:441} INFO - ::group::Post task execution logs
[2024-09-05T01:22:36.874+0000] {taskinstance.py:2905} ERROR - Task failed with exception
Traceback (most recent call last):
  File "/home/airflow/.local/lib/python3.12/site-packages/airflow/models/taskinstance.py", line 465, in _execute_task
    result = _execute_callable(context=context, **execute_callable_kwargs)
             ^^^^^^^^^^^^^^^^^^^^^^^^^^^^^^^^^^^^^^^^^^^^^^^^^^^^^^^^^^^^^
  File "/home/airflow/.local/lib/python3.12/site-packages/airflow/models/taskinstance.py", line 432, in _execute_callable
    return execute_callable(context=context, **execute_callable_kwargs)
           ^^^^^^^^^^^^^^^^^^^^^^^^^^^^^^^^^^^^^^^^^^^^^^^^^^^^^^^^^^^^
  File "/home/airflow/.local/lib/python3.12/site-packages/airflow/models/baseoperator.py", line 401, in wrapper
    return func(self, *args, **kwargs)
           ^^^^^^^^^^^^^^^^^^^^^^^^^^^
  File "/home/airflow/.local/lib/python3.12/site-packages/airflow/operators/bash.py", line 243, in execute
    raise AirflowException(
airflow.exceptions.AirflowException: Bash command failed. The command returned a non-zero exit code 1.
[2024-09-05T01:22:36.885+0000] {taskinstance.py:1206} INFO - Marking task as FAILED. dag_id=otro_dag, task_id=bash_task, run_id=manual__2024-09-05T01:22:35.758121+00:00, execution_date=20240905T012235, start_date=20240905T012236, end_date=20240905T012236
[2024-09-05T01:22:36.916+0000] {warnings.py:112} WARNING - /home/***/.local/lib/python3.12/site-packages/***/utils/email.py:154: RemovedInAirflow3Warning: Fetching SMTP credentials from configuration variables will be deprecated in a future release. Please set credentials using a connection instead.
  send_mime_email(e_from=mail_from, e_to=recipients, mime_msg=msg, conn_id=conn_id, dryrun=dryrun)

[2024-09-05T01:22:36.916+0000] {email.py:271} INFO - Email alerting: attempt 1
[2024-09-05T01:22:37.193+0000] {email.py:282} INFO - Sent an alert email to ['anderson.coder.space@gmail.com']
[2024-09-05T01:22:37.707+0000] {standard_task_runner.py:110} ERROR - Failed to execute job 9 for task bash_task (Bash command failed. The command returned a non-zero exit code 1.; 148)
[2024-09-05T01:22:37.742+0000] {local_task_job_runner.py:240} INFO - Task exited with return code 1
[2024-09-05T01:22:37.760+0000] {taskinstance.py:3503} INFO - 0 downstream tasks scheduled from follow-on schedule check
[2024-09-05T01:22:37.779+0000] {local_task_job_runner.py:222} INFO - ::endgroup::
